<?xml version='1.0'?>
<robot name="dd_robot">

  <gazebo>
    <static>False</static>
  </gazebo>


  <link name="dummy"/>

  <!-- Base Link -->
  <link name="base_link">
    <visual>
      <material name="black">
        <color rgba="0 0 0 1"/>
      </material>
      <origin xyz="0 0 0" rpy="0 0 0" />
      <geometry>
          <box size="1 1 0.5"/>
      </geometry>
    </visual>
    <!-- Base collision, mass and inertia -->
    <collision>
      <origin xyz="0 0 0" rpy="0 0 0" />
      <geometry>
          <box size="1 1 0.5"/>
      </geometry>
    </collision>
    <inertial>
      <mass value="5"/>
      <inertia ixx="0.13" ixy="0.0" ixz="0.0" iyy="0.21" iyz="0.0" izz="0.13"/>
    </inertial>

  </link>

  <gazebo reference="base_link">
    <material>Gazebo/Black</material>
  </gazebo>

  <joint name="dummy_joint" type="fixed">
    <parent link="dummy"/>
    <child link="base_link"/>
  </joint>

  <!-- Right Wheel -->
  <link name="right_wheel_front">
    <visual>
      <material name="white">
        <color rgba="1 1 1 1"/>
      </material>
      <origin xyz="0 0 0" rpy="1.570795 0 0" />
      <geometry>
          <cylinder length="0.2" radius="0.2" />
      </geometry>
    </visual>
    <!-- Right Wheel collision, mass and inertia -->
    <collision>
      <origin xyz="0 0 0" rpy="1.570795 0 0" />
      <geometry>
          <cylinder length="0.2" radius="0.2" />
      </geometry>
    </collision>
    <inertial>
      <mass value="0.5"/>
      <inertia ixx="0.01" ixy="0.0" ixz="0.0" iyy="0.005" iyz="0.0" izz="0.005"/>
    </inertial>

  </link>
  <gazebo reference="right_wheel_front">
    <material>Gazebo/White</material>
  </gazebo>

  <link name="right_wheel_back">
    <visual>
      <material name="white">
        <color rgba="1 1 1 1"/>
      </material>
      <origin xyz="0 0 0" rpy="1.570795 0 0" />
      <geometry>
          <cylinder length="0.2" radius="0.2" />
      </geometry>
    </visual>
    <!-- Right Wheel collision, mass and inertia -->
    <collision>
      <origin xyz="0 0 0" rpy="1.570795 0 0" />
      <geometry>
          <cylinder length="0.2" radius="0.2" />
      </geometry>
    </collision>
    <inertial>
      <mass value="0.5"/>
      <inertia ixx="0.01" ixy="0.0" ixz="0.0" iyy="0.005" iyz="0.0" izz="0.005"/>
    </inertial>

  </link>

  <gazebo reference="right_wheel_back">
    <material>Gazebo/White</material>
  </gazebo>

  <!-- Right Wheel joint -->
  <joint name="joint_right_wheel_back" type="continuous">
    <parent link="base_link"/>
    <child link="right_wheel_back"/>
    <origin xyz="-0.4 -0.60 -0.3" rpy="0 0 0" /> 
    <axis xyz="0 1 0" />
  </joint>
  <!-- Right Wheel joint -->
  <joint name="joint_right_wheel_front" type="continuous">
    <parent link="base_link"/>
    <child link="right_wheel_front"/>
    <origin xyz="0.4 -0.60 -0.3" rpy="0 0 0" /> 
    <axis xyz="0 1 0" />
  </joint>
  <!-- Left Wheel -->
  <link name="left_wheel_front">
    <visual>
      <material name="white">
        <color rgba="1 1 1 1"/>
      </material>
      <origin xyz="0 0 0" rpy="1.570795 0 0" />
      <geometry>
          <cylinder length="0.2" radius="0.2" />
      </geometry>
    </visual>
    <!-- Left Wheel collision, mass and inertia -->
    <collision>
      <origin xyz="0 0 0" rpy="1.570795 0 0" />
      <geometry>
          <cylinder length="0.2" radius="0.2" />
      </geometry>
    </collision>
    <inertial>
      <mass value="0.5"/>
      <inertia ixx="0.01" ixy="0.0" ixz="0.0" iyy="0.005" iyz="0.0" izz="0.005"/>
    </inertial>

  </link>

  <gazebo reference="left_wheel_front">
    <material>Gazebo/White</material>
  </gazebo>

  <!-- Left Wheel joint -->
  <joint name="joint_left_wheel_front" type="continuous">
    <parent link="base_link"/>
    <child link="left_wheel_front"/>
    <origin xyz="0.4 0.60 -0.3" rpy="0 0 0" /> 
    <axis xyz="0 1 0"/>
  </joint>
  <link name="left_wheel_back">
    <visual>
      <material name="white">
        <color rgba="1 1 1 1"/>
      </material>
      <origin xyz="0 0 0" rpy="1.570795 0 0" />
      <geometry>
          <cylinder length="0.2" radius="0.2" />
      </geometry>
    </visual>
    <!-- Left Wheel collision, mass and inertia -->
    <collision>
      <origin xyz="0 0 0" rpy="1.570795 0 0" />
      <geometry>
          <cylinder length="0.2" radius="0.2" />
      </geometry>
    </collision>
    <inertial>
      <mass value="0.5"/>
      <inertia ixx="0.01" ixy="0.0" ixz="0.0" iyy="0.005" iyz="0.0" izz="0.005"/>
    </inertial>

  </link>

  <gazebo reference="left_wheel_back">
    <material>Gazebo/White</material>
  </gazebo>

  <!-- Left Wheel joint -->
  <joint name="joint_left_wheel_back" type="continuous">
    <parent link="base_link"/>
    <child link="left_wheel_back"/>
    <origin xyz="-0.4 0.60 -0.3" rpy="0 0 0" /> 
    <axis xyz="0 1 0"/>
  </joint>
<gazebo>
  <plugin name="skid_steer_drive_controller" filename="libgazebo_ros_skid_steer_drive.so">
    <updateRate>100.0</updateRate>
    <robotNamespace>/</robotNamespace>
    <leftFrontJoint>joint_left_wheel_front</leftFrontJoint>
    <rightFrontJoint>joint_right_wheel_front</rightFrontJoint>
    <leftRearJoint>joint_left_wheel_back</leftRearJoint>
    <rightRearJoint>joint_right_wheel_back</rightRearJoint>
    <wheelSeparation>1</wheelSeparation>
    <wheelDiameter>0.4</wheelDiameter>
    <robotBaseFrame>base_link</robotBaseFrame>
    <torque>20</torque>
    <topicName>cmd_vel</topicName>
    <broadcastTF>false</broadcastTF>
  </plugin>
</gazebo>

</robot>