<?xml version="1.0"?>

<robot name="four_wheel_bot" xmlns:xacro = "https://www.ros.org/wiki/xacro">

    <xacro:macro name='wheel_link' params='link_name'>
        <link name="${link_name}">
            <inertial>
                <origin xyz="0 0 0" rpy="0 1.57 1.57"/>
                <mass value="0.5"/>
                <inertia ixx="0.01" ixy="0" ixz="0" iyy="0.005" iyz="0" izz="0.005"/>
            </inertial>
            
            <collision>
                <origin xyz="0 0 0" rpy="0 1.57 1.57"/>
                <geometry>
                    <cylinder radius="0.2" length="0.1"/>
                </geometry>
            </collision>

            <visual>
                <origin xyz="0 0 0" rpy="0 1.57 1.57"/>
                <geometry>
                    <cylinder radius="0.2" length="0.1"/>
                </geometry>
                <material name="black">
                  <color rgba="0.05 0.05 0.05 1"/>
                </material>
            </visual>
        </link>
    </xacro:macro>

    <xacro:macro name='joint_link' params='joint_name child origin_xyz'>
        <joint name="${joint_name}" type="continuous">
            <origin xyz="${origin_xyz}" rpy="0 0 0"/>
            <parent link="base_link"/>
            <child link="${child}"/>
            <axis xyz="0 1 0"/>
        </joint>
    </xacro:macro>

</robot>
